[DEBUG] [2020-11-20 02:40:31,039] [5052:140278284748608] - pool.py[line:129]: No connection available in pool.
[DEBUG] [2020-11-20 02:40:31,061] [5052:140278284748608] - pool.py[line:158]: Created new connection 140277666101344.
[DEBUG] [2020-11-20 02:40:31,069] [5052:140278284748608] - peewee.py[line:2863]: ('SELECT `t1`.`f_create_date`, `t1`.`f_update_date`, `t1`.`f_name`, `t1`.`f_namespace`, `t1`.`f_address`, `t1`.`f_engine`, `t1`.`f_type`, `t1`.`f_options`, `t1`.`f_partitions`, `t1`.`f_id_delimiter`, `t1`.`f_in_serialized`, `t1`.`f_have_head`, `t1`.`f_schema`, `t1`.`f_count`, `t1`.`f_part_of_data`, `t1`.`f_description`, `t1`.`f_create_time`, `t1`.`f_update_time` FROM `t_storage_table_meta` AS `t1` WHERE ((`t1`.`f_name` = %s) AND (`t1`.`f_namespace` = %s))', ['a68a62442ad911ebabeb4e9ecd9d57e8', 'output_data_202011200231350021282_hetero_lr_0_0'])
[DEBUG] [2020-11-20 02:40:31,082] [5052:140278284748608] - pool.py[line:185]: Returning 140277666101344 to pool.
